<!-- ======================================================
    This file is part of WAM-Hand-Track System.     
    Copyright UNM AgMan Lab.
           
    Author      :: Longsen Gao
        Contacts    : longsengao@gmail.com
        Last edits  : 27Jul'22
        Feel free to contact me if you have any questions, thanks!
====================================================== -->

<mujoco model="bhand282">
    <compiler coordinate="local" angle="radian" meshdir="meshes/" texturedir="textures/"/>
    
    <visual>
        <rgba haze="0.15 0.25 0.35 1"/>
        <quality shadowsize="2048"/>
        <map stiffness="700" shadowscale="0.5" fogstart="10" fogend="15" zfar="40" haze="0.3" />
    </visual>

    <!--<include file="include_bhand_Dependencies.xml"/>-->
    <asset>
        <mesh file="bhand_palm_fine.stl"/>
		<mesh file="bhand_palm_link_convex_decomposition_p1.stl"/>
		<mesh file="bhand_palm_link_convex_decomposition_p2.stl"/>
		<mesh file="bhand_palm_link_convex_decomposition_p3.stl"/>
		<mesh file="bhand_palm_link_convex_decomposition_p4.stl"/>
		<mesh file="bhand_finger_prox_link_fine.stl"/>
		<mesh file="bhand_finger_prox_link_convex_decomposition_p1.stl"/>
		<mesh file="bhand_finger_prox_link_convex_decomposition_p2.stl"/>
		<mesh file="bhand_finger_prox_link_convex_decomposition_p3.stl"/>
		<mesh file="bhand_finger_med_link_fine.stl"/>
        <mesh file="bhand_finger_med_link_convex.stl"/>
		<mesh file="bhand_finger_dist_link_fine.stl"/>
		<mesh file="bhand_finger_dist_link_convex.stl"/>
        <texture name="texplane" type="2d" builtin="checker" rgb1=".2 .3 .4" rgb2=".1 0.15 0.2" width="512"
                 height="512" mark="cross" markrgb=".8 .8 .8"/>
        <material name="matplane" reflectance="0.3" texture="texplane" texrepeat="1 1" texuniform="true"/>
    </asset>

    <default>
        <default class="wam/bhand">
            <joint type="hinge" limited="true" pos="0 0 0" axis="0 0 1"  frictionloss=".001"/>
        </default>
        <default class="wam/bhand/col">
            <geom type="mesh" contype="1" conaffinity="1" group="0" rgba="0.5 0.6 0.7 0.7"/>          
        </default>
        <default class="wam/bhand/viz">
            <geom type="mesh" contype="1" conaffinity="0" group="1" rgba="0.7 0.8 0.8 1"/>
        </default>
    </default>

<worldbody>
    <light directional="false" diffuse=".2 .2 .2" specular="0 0 0" pos="0 0 5" dir="0 0 -1" castshadow="false"/>
    <light mode="targetbodycom" target="wam/bhand/bhand_palm_link" directional="false" diffuse="2 2 2" specular="0.3 0.3 0.3" pos="0 0 4.0" dir="0 0 -1"/>
    <geom name="floor" pos="0 0 0" size="0.5 0.5 .25" type="plane" material="matplane" condim="3" solref="-16000 -200"/>
    <body name="wam/bhand/bhand_palm_link" childclass="wam/bhand" pos="0 0 0">
        <inertial pos="5.0019e-005  0.0044561 0.037268" mass="0.60858" fullinertia="0.0006986 0.00050354 0.00062253 2.7577e-007 -7.8138e-007 -6.44e-005" /> -->
        <geom class="wam/bhand/viz" mesh="bhand_palm_fine"/>
        <geom class="wam/bhand/col" mesh="bhand_palm_link_convex_decomposition_p1"/>
        <geom class="wam/bhand/col" mesh="bhand_palm_link_convex_decomposition_p2"/>
        <geom class="wam/bhand/col" mesh="bhand_palm_link_convex_decomposition_p3"/>
        <geom class="wam/bhand/col" mesh="bhand_palm_link_convex_decomposition_p4"/>
        

        <body name="wam/bhand/finger_1/prox_link" pos="-0.025 0 0.0415" quat="0.707107 0 0 -0.707107">
            <inertial pos="0.030616 7.3219e-005 0.011201" mass="0.14109" fullinertia="2.0672e-005 7.4105e-005 6.8207e-005 2.6024e-007 6.3481e-006 1.7118e-008" />
            <joint name="bhand/f1/prox" axis="0 0 -1" range="0 3.1415926536" damping="0.11"/>
            <geom class="wam/bhand/viz" mesh="bhand_finger_prox_link_fine"/>
            <geom class="wam/bhand/col" mesh="bhand_finger_prox_link_convex_decomposition_p1"/>
            <geom class="wam/bhand/col" mesh="bhand_finger_prox_link_convex_decomposition_p2"/>
            <geom class="wam/bhand/col" mesh="bhand_finger_prox_link_convex_decomposition_p3"/>
            
            <!-- IMPORTANT: with fingertip torque sensor -->
            <body name="wam/bhand/finger_1/med_link" pos="0.05 0 0.0339" quat="0.707107 0.707107 0 0">
                <inertial pos="0.023133 0.00078642 0.00052792" mass="0.062139" fullinertia="4.8162e-006 4.3317e-005 4.4441e-005 5.7981e-007 -7.2483e-007 -2.6653e-009" />
                <joint name="bhand/f1/med" range="0 2.4434609528 rad" damping="0.11"/>
                <geom class="wam/bhand/viz" mesh="bhand_finger_med_link_fine"/>
                <geom class="wam/bhand/col" mesh="bhand_finger_med_link_convex"/>
                
                <!-- IMPORTANT: with fingertip pressure pad -->
                <body name="wam/bhand/finger_1/dist_link" pos="0.06994 0.003 0" quat="0.92388 0 0 0.382683">
                    <inertial pos="0.02295 0.0010739 0.00041752" mass="0.04166" fullinertia="3.1199e-006 1.6948e-005 1.5809e-005 4.5115e-007 -2.9813e-007 -1.8635e-008" />
                    <joint name="bhand/f1/dist" range="0 0.837758041" damping="0.11"/>
                    <geom class="wam/bhand/viz" mesh="bhand_finger_dist_link_fine" euler="0 0 -.84"/>
                    <geom class="wam/bhand/col" mesh="bhand_finger_dist_link_convex" euler="0 0 -.84"/> 
                    <site name="sensorsurf1_0_1" pos="0.024 0.0060 0.006" size=".002 .002 .003" type="box" rgba="0.3 0.2 0.1 0.3" euler="0 0 -0.10"/>
                    <site name="sensorsurf1_0_2" pos="0.024 0.0060 0.000" size=".002 .002 .003" type="box" rgba="0.3 0.2 0.1 0.3" euler="0 0 -0.10"/>
                    <site name="sensorsurf1_0_3" pos="0.024 0.0060 -0.006" size=".002 .002 .003" type="box" rgba="0.3 0.2 0.1 0.3" euler="0 0 -0.10"/>  
                    <site name="sensorsurf1_1_1" pos="0.028 0.0053 0.006" size=".002 .002 .003" type="box" rgba="0.3 0.2 0.1 0.3" euler="0 0 -0.10"/>
                    <site name="sensorsurf1_1_2" pos="0.028 0.0053 0.000" size=".002 .002 .003" type="box" rgba="0.3 0.2 0.1 0.3" euler="0 0 -0.10"/>
                    <site name="sensorsurf1_1_3" pos="0.028 0.0053 -0.006" size=".002 .002 .003" type="box" rgba="0.3 0.2 0.1 0.3" euler="0 0 -0.10"/>  
                    <site name="sensorsurf1_2_1" pos="0.032 0.0047 0.006" size=".002 .002 .003" type="box" rgba="0.3 0.2 0.1 0.3" euler="0 0 -0.10"/>
                    <site name="sensorsurf1_2_2" pos="0.032 0.0047 0.000" size=".002 .002 .003" type="box" rgba="0.3 0.2 0.1 0.3" euler="0 0 -0.10"/>
                    <site name="sensorsurf1_2_3" pos="0.032 0.0047 -0.006" size=".002 .002 .003" type="box" rgba="0.3 0.2 0.1 0.3" euler="0 0 -0.10"/>  
                    <site name="sensorsurf1_3_1" pos="0.036 0.004 0.006" size=".002 .002 .003" type="box" rgba="0.3 0.2 0.1 0.3" euler="0 0 -0.20"/>
                    <site name="sensorsurf1_3_2" pos="0.036 0.004 0.000" size=".002 .002 .003" type="box" rgba="0.3 0.2 0.1 0.3" euler="0 0 -0.20"/>
                    <site name="sensorsurf1_3_3" pos="0.036 0.004 -0.006" size=".002 .002 .003" type="box" rgba="0.3 0.2 0.1 0.3" euler="0 0 -0.20"/>                                                            
                    <site name="sensorsurf1_4_1" pos="0.04 0.0035 0.006" size=".002 .002 .003" type="box" rgba="0.3 0.2 0.1 0.3" euler="0 0 -0.20"/>
                    <site name="sensorsurf1_4_2" pos="0.04 0.0035 0.000" size=".002 .002 .003" type="box" rgba="0.3 0.2 0.1 0.3" euler="0 0 -0.20"/>
                    <site name="sensorsurf1_4_3" pos="0.04 0.0035 -0.006" size=".002 .002 .003" type="box" rgba="0.3 0.2 0.1 0.3" euler="0 0 -0.20"/>
                    <site name="sensorsurf1_5_1" pos="0.044 0.0026 0.006" size=".002 .002 .003" type="box" rgba="0.3 0.2 0.1 0.3" euler="0 0 -0.20"/>
                    <site name="sensorsurf1_5_2" pos="0.044 0.0026 0.000" size=".002 .002 .003" type="box" rgba="0.3 0.2 0.1 0.3" euler="0 0 -0.20"/>
                    <site name="sensorsurf1_5_3" pos="0.044 0.0026 -0.006" size=".002 .002 .003" type="box" rgba="0.3 0.2 0.1 0.3" euler="0 0 -0.20"/>
                    <site name="sensorsurf1_6_1" pos="0.048 0.0018 0.006" size=".002 .002 .003" type="box" rgba="0.3 0.2 0.1 0.3" euler="0 0 -0.20"/>
                    <site name="sensorsurf1_6_2" pos="0.048 0.0018 0.000" size=".002 .002 .003" type="box" rgba="0.3 0.2 0.1 0.3" euler="0 0 -0.20"/>
                    <site name="sensorsurf1_6_3" pos="0.048 0.0018 -0.006" size=".002 .002 .003" type="box" rgba="0.3 0.2 0.1 0.3" euler="0 0 -0.20"/>
                    <site name="sensorsurf1_7_1" pos="0.052 0.0000 0.006" size=".002 .002 .003" type="box" rgba="0.3 0.2 0.1 0.3" euler="0 0 -0.20"/>
                    <site name="sensorsurf1_7_2" pos="0.052 0.0000 0.000" size=".002 .002 .003" type="box" rgba="0.3 0.2 0.1 0.3" euler="0 0 -0.20"/>
                    <site name="sensorsurf1_7_3" pos="0.052 0.0000 -0.006" size=".002 .002 .003" type="box" rgba="0.3 0.2 0.1 0.3" euler="0 0 -0.20"/>
                </body>
            </body>
        </body>
        
        <body name="wam/bhand/finger_2/prox_link" pos="0.025 0 0.0415" quat="0.707107 0 0 -0.707107">
            <inertial pos="0.030616 7.3219e-005 0.011201" mass="0.14109" fullinertia="2.0672e-005 7.4105e-005 6.8207e-005 2.6024e-007 6.3481e-006 1.7118e-008" />
            <joint name="bhand/f2/prox" range="0 3.1415926536" damping="0.11"/>
            <geom class="wam/bhand/viz" mesh="bhand_finger_prox_link_fine"/>
            <geom class="wam/bhand/col" mesh="bhand_finger_prox_link_convex_decomposition_p1"/>
            <geom class="wam/bhand/col" mesh="bhand_finger_prox_link_convex_decomposition_p2"/>
            <geom class="wam/bhand/col" mesh="bhand_finger_prox_link_convex_decomposition_p3"/>
            
            <!-- IMPORTANT: with fingertip torque sensor -->
            <body name="wam/bhand/finger_2/med_link" pos="0.05 0 0.0339" quat="0.707107 0.707107 0 0">
                <inertial pos="0.023133 0.00078642 0.00052792" mass="0.062139" fullinertia="4.8162e-006 4.3317e-005 4.4441e-005 5.7981e-007 -7.2483e-007 -2.6653e-009" />
                <joint name="bhand/f2/med" range="0 2.4434609528 rad" damping="0.11"/>
                <geom class="wam/bhand/viz" mesh="bhand_finger_med_link_fine"/>
                <geom class="wam/bhand/col" mesh="bhand_finger_med_link_convex"/>
                
                <!-- IMPORTANT: with fingertip pressure pad -->
                <body name="wam/bhand/finger_2/dist_link" pos="0.06994 0.003 0" quat="0.92388 0 0 0.382683">
                    <inertial pos="0.02295 0.0010739 0.00041752" mass="0.04166" fullinertia="3.1199e-006 1.6948e-005 1.5809e-005 4.5115e-007 -2.9813e-007 -1.8635e-008" />
                    <joint name="bhand/f2/dist" range="0 0.837758041" damping="0.11"/>
                    <geom class="wam/bhand/viz" mesh="bhand_finger_dist_link_fine" euler="0 0 -.84"/>
                    <geom class="wam/bhand/col" mesh="bhand_finger_dist_link_convex" euler="0 0 -.84"/> 
                    <site name="sensorsurf2_0_1" pos="0.024 0.0060 0.006" size=".002 .002 .003" type="box" rgba="0.3 0.2 0.1 0.3" euler="0 0 -0.10"/>
                    <site name="sensorsurf2_0_2" pos="0.024 0.0060 0.000" size=".002 .002 .003" type="box" rgba="0.3 0.2 0.1 0.3" euler="0 0 -0.10"/>
                    <site name="sensorsurf2_0_3" pos="0.024 0.0060 -0.006" size=".002 .002 .003" type="box" rgba="0.3 0.2 0.1 0.3" euler="0 0 -0.10"/>  
                    <site name="sensorsurf2_1_1" pos="0.028 0.0053 0.006" size=".002 .002 .003" type="box" rgba="0.3 0.2 0.1 0.3" euler="0 0 -0.10"/>
                    <site name="sensorsurf2_1_2" pos="0.028 0.0053 0.000" size=".002 .002 .003" type="box" rgba="0.3 0.2 0.1 0.3" euler="0 0 -0.10"/>
                    <site name="sensorsurf2_1_3" pos="0.028 0.0053 -0.006" size=".002 .002 .003" type="box" rgba="0.3 0.2 0.1 0.3" euler="0 0 -0.10"/>  
                    <site name="sensorsurf2_2_1" pos="0.032 0.0047 0.006" size=".002 .002 .003" type="box" rgba="0.3 0.2 0.1 0.3" euler="0 0 -0.10"/>
                    <site name="sensorsurf2_2_2" pos="0.032 0.0047 0.000" size=".002 .002 .003" type="box" rgba="0.3 0.2 0.1 0.3" euler="0 0 -0.10"/>
                    <site name="sensorsurf2_2_3" pos="0.032 0.0047 -0.006" size=".002 .002 .003" type="box" rgba="0.3 0.2 0.1 0.3" euler="0 0 -0.10"/>  
                    <site name="sensorsurf2_3_1" pos="0.036 0.004 0.006" size=".002 .002 .003" type="box" rgba="0.3 0.2 0.1 0.3" euler="0 0 -0.20"/>
                    <site name="sensorsurf2_3_2" pos="0.036 0.004 0.000" size=".002 .002 .003" type="box" rgba="0.3 0.2 0.1 0.3" euler="0 0 -0.20"/>
                    <site name="sensorsurf2_3_3" pos="0.036 0.004 -0.006" size=".002 .002 .003" type="box" rgba="0.3 0.2 0.1 0.3" euler="0 0 -0.20"/>                                                            
                    <site name="sensorsurf2_4_1" pos="0.04 0.0035 0.006" size=".002 .002 .003" type="box" rgba="0.3 0.2 0.1 0.3" euler="0 0 -0.20"/>
                    <site name="sensorsurf2_4_2" pos="0.04 0.0035 0.000" size=".002 .002 .003" type="box" rgba="0.3 0.2 0.1 0.3" euler="0 0 -0.20"/>
                    <site name="sensorsurf2_4_3" pos="0.04 0.0035 -0.006" size=".002 .002 .003" type="box" rgba="0.3 0.2 0.1 0.3" euler="0 0 -0.20"/>
                    <site name="sensorsurf2_5_1" pos="0.044 0.0026 0.006" size=".002 .002 .003" type="box" rgba="0.3 0.2 0.1 0.3" euler="0 0 -0.20"/>
                    <site name="sensorsurf2_5_2" pos="0.044 0.0026 0.000" size=".002 .002 .003" type="box" rgba="0.3 0.2 0.1 0.3" euler="0 0 -0.20"/>
                    <site name="sensorsurf2_5_3" pos="0.044 0.0026 -0.006" size=".002 .002 .003" type="box" rgba="0.3 0.2 0.1 0.3" euler="0 0 -0.20"/>
                    <site name="sensorsurf2_6_1" pos="0.048 0.0018 0.006" size=".002 .002 .003" type="box" rgba="0.3 0.2 0.1 0.3" euler="0 0 -0.20"/>
                    <site name="sensorsurf2_6_2" pos="0.048 0.0018 0.000" size=".002 .002 .003" type="box" rgba="0.3 0.2 0.1 0.3" euler="0 0 -0.20"/>
                    <site name="sensorsurf2_6_3" pos="0.048 0.0018 -0.006" size=".002 .002 .003" type="box" rgba="0.3 0.2 0.1 0.3" euler="0 0 -0.20"/>
                    <site name="sensorsurf2_7_1" pos="0.052 0.0000 0.006" size=".002 .002 .003" type="box" rgba="0.3 0.2 0.1 0.3" euler="0 0 -0.20"/>
                    <site name="sensorsurf2_7_2" pos="0.052 0.0000 0.000" size=".002 .002 .003" type="box" rgba="0.3 0.2 0.1 0.3" euler="0 0 -0.20"/>
                    <site name="sensorsurf2_7_3" pos="0.052 0.0000 -0.006" size=".002 .002 .003" type="box" rgba="0.3 0.2 0.1 0.3" euler="0 0 -0.20"/>
                </body>
            </body>
        </body>
        
        <!-- IMPORTANT: with fingertip torque sensor -->
        <body name="wam/bhand/finger_3/med_link" pos="0 0.05 0.0754" quat="0.5 0.5 0.5 0.5">
            <inertial  pos="0.023133 0.00078642 0.00052792" mass="0.062139" fullinertia="4.8162e-006 4.3317e-005 4.4441e-005 5.7981e-007 -7.2483e-007 -2.6653e-009" />
            <joint name="bhand/f3/med" range="0 2.4434609528 rad" damping="0.11"/>
            <geom class="wam/bhand/viz" mesh="bhand_finger_med_link_fine"/>
            <geom class="wam/bhand/col" mesh="bhand_finger_med_link_convex"/>
            
            <!-- IMPORTANT: with fingertip pressure pad -->
            <body name="wam/bhand/finger_3/dist_link" pos="0.06994 0.003 0" quat="0.92388 0 0 0.382683">
                <inertial pos="0.02295 0.0010739 0.00041752" mass="0.04166" fullinertia="3.1199e-006 1.6948e-005 1.5809e-005 4.5115e-007 -2.9813e-007 -1.8635e-008" />
                <joint name="bhand/f3/dist" range="0 0.837758041" damping="0.11"/>
                <geom class="wam/bhand/viz" mesh="bhand_finger_dist_link_fine" euler="0 0 -.84"/>
                <geom class="wam/bhand/col" mesh="bhand_finger_dist_link_convex" euler="0 0 -.84"/> 
                    <site name="sensorsurf3_0_1" pos="0.024 0.0060 0.006" size=".002 .002 .003" type="box" rgba="0.3 0.2 0.1 0.3" euler="0 0 -0.10"/>
                    <site name="sensorsurf3_0_2" pos="0.024 0.0060 0.000" size=".002 .002 .003" type="box" rgba="0.3 0.2 0.1 0.3" euler="0 0 -0.10"/>
                    <site name="sensorsurf3_0_3" pos="0.024 0.0060 -0.006" size=".002 .002 .003" type="box" rgba="0.3 0.2 0.1 0.3" euler="0 0 -0.10"/>  
                    <site name="sensorsurf3_1_1" pos="0.028 0.0053 0.006" size=".002 .002 .003" type="box" rgba="0.3 0.2 0.1 0.3" euler="0 0 -0.10"/>
                    <site name="sensorsurf3_1_2" pos="0.028 0.0053 0.000" size=".002 .002 .003" type="box" rgba="0.3 0.2 0.1 0.3" euler="0 0 -0.10"/>
                    <site name="sensorsurf3_1_3" pos="0.028 0.0053 -0.006" size=".002 .002 .003" type="box" rgba="0.3 0.2 0.1 0.3" euler="0 0 -0.10"/>  
                    <site name="sensorsurf3_2_1" pos="0.032 0.0047 0.006" size=".002 .002 .003" type="box" rgba="0.3 0.2 0.1 0.3" euler="0 0 -0.10"/>
                    <site name="sensorsurf3_2_2" pos="0.032 0.0047 0.000" size=".002 .002 .003" type="box" rgba="0.3 0.2 0.1 0.3" euler="0 0 -0.10"/>
                    <site name="sensorsurf3_2_3" pos="0.032 0.0047 -0.006" size=".002 .002 .003" type="box" rgba="0.3 0.2 0.1 0.3" euler="0 0 -0.10"/>  
                    <site name="sensorsurf3_3_1" pos="0.036 0.004 0.006" size=".002 .002 .003" type="box" rgba="0.3 0.2 0.1 0.3" euler="0 0 -0.20"/>
                    <site name="sensorsurf3_3_2" pos="0.036 0.004 0.000" size=".002 .002 .003" type="box" rgba="0.3 0.2 0.1 0.3" euler="0 0 -0.20"/>
                    <site name="sensorsurf3_3_3" pos="0.036 0.004 -0.006" size=".002 .002 .003" type="box" rgba="0.3 0.2 0.1 0.3" euler="0 0 -0.20"/>                                                            
                    <site name="sensorsurf3_4_1" pos="0.04 0.0035 0.006" size=".002 .002 .003" type="box" rgba="0.3 0.2 0.1 0.3" euler="0 0 -0.20"/>
                    <site name="sensorsurf3_4_2" pos="0.04 0.0035 0.000" size=".002 .002 .003" type="box" rgba="0.3 0.2 0.1 0.3" euler="0 0 -0.20"/>
                    <site name="sensorsurf3_4_3" pos="0.04 0.0035 -0.006" size=".002 .002 .003" type="box" rgba="0.3 0.2 0.1 0.3" euler="0 0 -0.20"/>
                    <site name="sensorsurf3_5_1" pos="0.044 0.0026 0.006" size=".002 .002 .003" type="box" rgba="0.3 0.2 0.1 0.3" euler="0 0 -0.20"/>
                    <site name="sensorsurf3_5_2" pos="0.044 0.0026 0.000" size=".002 .002 .003" type="box" rgba="0.3 0.2 0.1 0.3" euler="0 0 -0.20"/>
                    <site name="sensorsurf3_5_3" pos="0.044 0.0026 -0.006" size=".002 .002 .003" type="box" rgba="0.3 0.2 0.1 0.3" euler="0 0 -0.20"/>
                    <site name="sensorsurf3_6_1" pos="0.048 0.0018 0.006" size=".002 .002 .003" type="box" rgba="0.3 0.2 0.1 0.3" euler="0 0 -0.20"/>
                    <site name="sensorsurf3_6_2" pos="0.048 0.0018 0.000" size=".002 .002 .003" type="box" rgba="0.3 0.2 0.1 0.3" euler="0 0 -0.20"/>
                    <site name="sensorsurf3_6_3" pos="0.048 0.0018 -0.006" size=".002 .002 .003" type="box" rgba="0.3 0.2 0.1 0.3" euler="0 0 -0.20"/>
                    <site name="sensorsurf3_7_1" pos="0.052 0.0000 0.006" size=".002 .002 .003" type="box" rgba="0.3 0.2 0.1 0.3" euler="0 0 -0.20"/>
                    <site name="sensorsurf3_7_2" pos="0.052 0.0000 0.000" size=".002 .002 .003" type="box" rgba="0.3 0.2 0.1 0.3" euler="0 0 -0.20"/>
                    <site name="sensorsurf3_7_3" pos="0.052 0.0000 -0.006" size=".002 .002 .003" type="box" rgba="0.3 0.2 0.1 0.3" euler="0 0 -0.20"/>
            </body>
        </body>
    </body>

        
        
</worldbody>
    
</mujoco>