<!-- ======================================================
    This file is part of WAM-Hand-Track System.     
    Copyright UNM AgMan Lab.
           
    Author      :: Longsen Gao
        Contacts    : longsengao@gmail.com
        Last edits  : 27Jul'22
        Feel free to contact me if you have any questions, thanks!
====================================================== -->

<mujocoinclude model="BH8-280"> 

<body name="wam/bhand/bhand_palm_link" pos="0 0 0.0" quat="0 0 0 1">
    <inertial pos="-5.1098e-005 0.0050433 0.036671" quat="0.553098 0.439047 0.434456 0.559078" mass="0.50573" diaginertia="0.000224052 0.000210701 2.81212e-005" />
    <site name="wam/mass_sites/bhand_palm_link" pos="-0.00007974 -0.00323552 -0.00016313"/>
    <geom class="viz" mesh="bhand_palm_fine"/>
    <geom class="col" mesh="bhand_palm_fine" material="RobMat"/>
    <body name="wam/bhand/finger_1/prox_link" pos="-0.025 0 0.0415" quat="0.707107 0 0 -0.707107">
        <inertial pos="0.023133 0.00078642 0.00052792" quat="0.0160796 0.707269 -0.000766008 0.706762" mass="0.14109" diaginertia="7.77335e-005 7.66282e-005 4.83122e-006" />
        <site name="wam/mass_sites/finger_1/prox_link" pos="-0.025 0 0.0415"/>
        <joint name="wam/bhand/finger_1/prox_joint" axis="0 0 -1" range="0 3.14159" damping="0.11"/>
        <geom class="wam/bhandViz" mesh="bhand_finger_prox_link_fine"/>
        <body name="wam/bhand/finger_1/med_link" pos="0.05 0 0.0339" quat="0.707107 0.707107 0 0">
            <inertial pos="0.023133 0.00078642 0.00052792" quat="0.0160796 0.707269 -0.000766008 0.706762" mass="0.062139" diaginertia="7.77335e-005 7.66282e-005 4.83122e-006" />
            <site name="wam/mass_sites/finger_1/med_link" pos="0.05 0 0.0339"/>
            <joint name="wam/bhand/finger_1/med_joint" range="0 2.44346" damping="0.11"/>
            <geom class="wam/bhandViz" mesh="bhand_finger_med_link_fine"/>
            <geom class="col" mesh="bhand_finger_prox_link_fine" material="RobMat"/>
            <body name="wam/bhand/finger_1/dist_link" pos="0.06994 0.003 0" quat="0.92388 0 0 0.382683">
                    <inertial pos="0.022825 0.0010491 0.0004203" quat="0.508412 0.51165 0.489583 0.489939" mass="0.041377" diaginertia="3.8434e-005 3.72753e-005 3.09987e-006" />
                    <joint name="wam/bhand/finger_1/dist_joint" range="0 0.837758" damping="0.11"/>
                    <geom class="wam/bhandViz" mesh="bhand_finger_dist_link_fine" euler="0 0 -.84"/>  
                    <geom class="col" mesh="bhand_finger_dist_link_fine" euler="0 0 -.84" material="RobMat"/>
                    <site name="sensorsurf1_0_1" pos="0.024 0.0060 0.006" size=".002 .002 .003" type="box" rgba="0.3 0.2 0.1 0.3" euler="0 0 -0.10"/>
                    <site name="sensorsurf1_0_2" pos="0.024 0.0060 0.000" size=".002 .002 .003" type="box" rgba="0.3 0.2 0.1 0.3" euler="0 0 -0.10"/>
                    <site name="sensorsurf1_0_3" pos="0.024 0.0060 -0.006" size=".002 .002 .003" type="box" rgba="0.3 0.2 0.1 0.3" euler="0 0 -0.10"/>  
                    <site name="sensorsurf1_1_1" pos="0.028 0.0053 0.006" size=".002 .002 .003" type="box" rgba="0.3 0.2 0.1 0.3" euler="0 0 -0.10"/>
                    <site name="sensorsurf1_1_2" pos="0.028 0.0053 0.000" size=".002 .002 .003" type="box" rgba="0.3 0.2 0.1 0.3" euler="0 0 -0.10"/>
                    <site name="sensorsurf1_1_3" pos="0.028 0.0053 -0.006" size=".002 .002 .003" type="box" rgba="0.3 0.2 0.1 0.3" euler="0 0 -0.10"/>  
                    <site name="sensorsurf1_2_1" pos="0.032 0.0047 0.006" size=".002 .002 .003" type="box" rgba="0.3 0.2 0.1 0.3" euler="0 0 -0.10"/>
                    <site name="sensorsurf1_2_2" pos="0.032 0.0047 0.000" size=".002 .002 .003" type="box" rgba="0.3 0.2 0.1 0.3" euler="0 0 -0.10"/>
                    <site name="sensorsurf1_2_3" pos="0.032 0.0047 -0.006" size=".002 .002 .003" type="box" rgba="0.3 0.2 0.1 0.3" euler="0 0 -0.10"/>  
                    <site name="sensorsurf1_3_1" pos="0.036 0.004 0.006" size=".002 .002 .003" type="box" rgba="0.3 0.2 0.1 0.3" euler="0 0 -0.20"/>
                    <site name="sensorsurf1_3_2" pos="0.036 0.004 0.000" size=".002 .002 .003" type="box" rgba="0.3 0.2 0.1 0.3" euler="0 0 -0.20"/>
                    <site name="sensorsurf1_3_3" pos="0.036 0.004 -0.006" size=".002 .002 .003" type="box" rgba="0.3 0.2 0.1 0.3" euler="0 0 -0.20"/>                                                            
                    <site name="sensorsurf1_4_1" pos="0.04 0.0035 0.006" size=".002 .002 .003" type="box" rgba="0.3 0.2 0.1 0.3" euler="0 0 -0.20"/>
                    <site name="sensorsurf1_4_2" pos="0.04 0.0035 0.000" size=".002 .002 .003" type="box" rgba="0.3 0.2 0.1 0.3" euler="0 0 -0.20"/>
                    <site name="sensorsurf1_4_3" pos="0.04 0.0035 -0.006" size=".002 .002 .003" type="box" rgba="0.3 0.2 0.1 0.3" euler="0 0 -0.20"/>
                    <site name="sensorsurf1_5_1" pos="0.044 0.0026 0.006" size=".002 .002 .003" type="box" rgba="0.3 0.2 0.1 0.3" euler="0 0 -0.20"/>
                    <site name="sensorsurf1_5_2" pos="0.044 0.0026 0.000" size=".002 .002 .003" type="box" rgba="0.3 0.2 0.1 0.3" euler="0 0 -0.20"/>
                    <site name="sensorsurf1_5_3" pos="0.044 0.0026 -0.006" size=".002 .002 .003" type="box" rgba="0.3 0.2 0.1 0.3" euler="0 0 -0.20"/>
                    <site name="sensorsurf1_6_1" pos="0.048 0.0018 0.006" size=".002 .002 .003" type="box" rgba="0.3 0.2 0.1 0.3" euler="0 0 -0.20"/>
                    <site name="sensorsurf1_6_2" pos="0.048 0.0018 0.000" size=".002 .002 .003" type="box" rgba="0.3 0.2 0.1 0.3" euler="0 0 -0.20"/>
                    <site name="sensorsurf1_6_3" pos="0.048 0.0018 -0.006" size=".002 .002 .003" type="box" rgba="0.3 0.2 0.1 0.3" euler="0 0 -0.20"/>
                    <site name="sensorsurf1_7_1" pos="0.052 0.0000 0.006" size=".002 .002 .003" type="box" rgba="0.3 0.2 0.1 0.3" euler="0 0 -0.20"/>
                    <site name="sensorsurf1_7_2" pos="0.052 0.0000 0.000" size=".002 .002 .003" type="box" rgba="0.3 0.2 0.1 0.3" euler="0 0 -0.20"/>
                    <site name="sensorsurf1_7_3" pos="0.052 0.0000 -0.006" size=".002 .002 .003" type="box" rgba="0.3 0.2 0.1 0.3" euler="0 0 -0.20"/>
                </body>
            </body>
        </body>
        <body name="wam/bhand/finger_2/prox_link" pos="0.025 0 0.0415" quat="0.707107 0 0 -0.707107">
            <inertial pos="0.023133 0.00078642 0.00052792" quat="0.0160796 0.707269 -0.000766008 0.706762" mass="0.14109" diaginertia="7.77335e-005 7.66282e-005 4.83122e-006" />
            <joint name="wam/bhand/finger_2/prox_joint" range="0 3.14159" damping="0.11"/>
            <geom class="wam/bhandViz" mesh="bhand_finger_prox_link_fine"/>
            <geom class="col" mesh="bhand_finger_prox_link_fine"/>
            <body name="wam/bhand/finger_2/med_link" pos="0.05 0 0.0339" quat="0.707107 0.707107 0 0">
                <inertial pos="0.023133 0.00078642 0.00052792" quat="0.0160796 0.707269 -0.000766008 0.706762" mass="0.062139" diaginertia="7.77335e-005 7.66282e-005 4.83122e-006" />
                <joint name="wam/bhand/finger_2/med_joint" range="0 2.44346" damping="0.11"/>
                <geom class="wam/bhandViz" mesh="bhand_finger_med_link_fine"/>
                <geom class="col" mesh="bhand_finger_med_link_fine" material="RobMat"/>                                                
                <body name="wam/bhand/finger_2/dist_link" pos="0.06994 0.003 0" quat="0.92388 0 0 0.382683">
                    <inertial pos="0.022825 0.0010491 0.0004203" quat="0.508412 0.51165 0.489583 0.489939" mass="0.041377" diaginertia="3.8434e-005 3.72753e-005 3.09987e-006" />
                    <joint name="wam/bhand/finger_2/dist_joint" range="0 0.837758" damping="0.11"/>
                    <geom class="wam/bhandViz" mesh="bhand_finger_dist_link_fine" euler="0 0 -.84"/>
                    <geom class="col" mesh="bhand_finger_dist_link_fine" euler="0 0 -.84" material="RobMat"/>
                    
                    <site name="sensorsurf2_0_1" pos="0.024 0.0060 0.006" size=".002 .002 .003" type="box" rgba="0.3 0.2 0.1 0.3" euler="0 0 -0.10"/>
                    <site name="sensorsurf2_0_2" pos="0.024 0.0060 0.000" size=".002 .002 .003" type="box" rgba="0.3 0.2 0.1 0.3" euler="0 0 -0.10"/>
                    <site name="sensorsurf2_0_3" pos="0.024 0.0060 -0.006" size=".002 .002 .003" type="box" rgba="0.3 0.2 0.1 0.3" euler="0 0 -0.10"/>  
                    <site name="sensorsurf2_1_1" pos="0.028 0.0053 0.006" size=".002 .002 .003" type="box" rgba="0.3 0.2 0.1 0.3" euler="0 0 -0.10"/>
                    <site name="sensorsurf2_1_2" pos="0.028 0.0053 0.000" size=".002 .002 .003" type="box" rgba="0.3 0.2 0.1 0.3" euler="0 0 -0.10"/>
                    <site name="sensorsurf2_1_3" pos="0.028 0.0053 -0.006" size=".002 .002 .003" type="box" rgba="0.3 0.2 0.1 0.3" euler="0 0 -0.10"/>  
                    <site name="sensorsurf2_2_1" pos="0.032 0.0047 0.006" size=".002 .002 .003" type="box" rgba="0.3 0.2 0.1 0.3" euler="0 0 -0.10"/>
                    <site name="sensorsurf2_2_2" pos="0.032 0.0047 0.000" size=".002 .002 .003" type="box" rgba="0.3 0.2 0.1 0.3" euler="0 0 -0.10"/>
                    <site name="sensorsurf2_2_3" pos="0.032 0.0047 -0.006" size=".002 .002 .003" type="box" rgba="0.3 0.2 0.1 0.3" euler="0 0 -0.10"/>  
                    <site name="sensorsurf2_3_1" pos="0.036 0.004 0.006" size=".002 .002 .003" type="box" rgba="0.3 0.2 0.1 0.3" euler="0 0 -0.20"/>
                    <site name="sensorsurf2_3_2" pos="0.036 0.004 0.000" size=".002 .002 .003" type="box" rgba="0.3 0.2 0.1 0.3" euler="0 0 -0.20"/>
                    <site name="sensorsurf2_3_3" pos="0.036 0.004 -0.006" size=".002 .002 .003" type="box" rgba="0.3 0.2 0.1 0.3" euler="0 0 -0.20"/>                                                            
                    <site name="sensorsurf2_4_1" pos="0.04 0.0035 0.006" size=".002 .002 .003" type="box" rgba="0.3 0.2 0.1 0.3" euler="0 0 -0.20"/>
                    <site name="sensorsurf2_4_2" pos="0.04 0.0035 0.000" size=".002 .002 .003" type="box" rgba="0.3 0.2 0.1 0.3" euler="0 0 -0.20"/>
                    <site name="sensorsurf2_4_3" pos="0.04 0.0035 -0.006" size=".002 .002 .003" type="box" rgba="0.3 0.2 0.1 0.3" euler="0 0 -0.20"/>
                    <site name="sensorsurf2_5_1" pos="0.044 0.0026 0.006" size=".002 .002 .003" type="box" rgba="0.3 0.2 0.1 0.3" euler="0 0 -0.20"/>
                    <site name="sensorsurf2_5_2" pos="0.044 0.0026 0.000" size=".002 .002 .003" type="box" rgba="0.3 0.2 0.1 0.3" euler="0 0 -0.20"/>
                    <site name="sensorsurf2_5_3" pos="0.044 0.0026 -0.006" size=".002 .002 .003" type="box" rgba="0.3 0.2 0.1 0.3" euler="0 0 -0.20"/>
                    <site name="sensorsurf2_6_1" pos="0.048 0.0018 0.006" size=".002 .002 .003" type="box" rgba="0.3 0.2 0.1 0.3" euler="0 0 -0.20"/>
                    <site name="sensorsurf2_6_2" pos="0.048 0.0018 0.000" size=".002 .002 .003" type="box" rgba="0.3 0.2 0.1 0.3" euler="0 0 -0.20"/>
                    <site name="sensorsurf2_6_3" pos="0.048 0.0018 -0.006" size=".002 .002 .003" type="box" rgba="0.3 0.2 0.1 0.3" euler="0 0 -0.20"/>
                    <site name="sensorsurf2_7_1" pos="0.052 0.0000 0.006" size=".002 .002 .003" type="box" rgba="0.3 0.2 0.1 0.3" euler="0 0 -0.20"/>
                    <site name="sensorsurf2_7_2" pos="0.052 0.0000 0.000" size=".002 .002 .003" type="box" rgba="0.3 0.2 0.1 0.3" euler="0 0 -0.20"/>
                    <site name="sensorsurf2_7_3" pos="0.052 0.0000 -0.006" size=".002 .002 .003" type="box" rgba="0.3 0.2 0.1 0.3" euler="0 0 -0.20"/>
                </body>
            </body>
        </body>
        <body name="wam/bhand/finger_3/med_link" pos="0 0.05 0.0754" quat="0.5 0.5 0.5 0.5">
            <inertial pos="0.023133 0.00078642 0.00052792" quat="0.0160796 0.707269 -0.000766008 0.706762" mass="0.062139" diaginertia="7.77335e-005 7.66282e-005 4.83122e-006" />
            <joint name="wam/bhand/finger_3/med_joint" range="0 2.44346" damping="0.11"/>
            <geom class="wam/bhandViz" mesh="bhand_finger_med_link_fine"/>
            <geom class="col" mesh="bhand_finger_med_link_fine" material="RobMat"/>
            <body name="wam/bhand/finger_3/dist_link" pos="0.06994 0.003 0" quat="0.92388 0 0 0.382683">
                <inertial pos="0.022825 0.0010491 0.0004203" quat="0.508412 0.51165 0.489583 0.489939" mass="0.041377" diaginertia="3.8434e-005 3.72753e-005 3.09987e-006" />
                <joint name="wam/bhand/finger_3/dist_joint" range="0 0.837758" damping="0.11"/>
                <geom class="wam/bhandViz" mesh="bhand_finger_dist_link_fine" euler="0 0 -.84"/>
                <geom class="col" mesh="bhand_finger_dist_link_fine" euler="0 0 -.84" material="RobMat"/>
                    <site name="sensorsurf3_0_1" pos="0.024 0.0060 0.006" size=".002 .002 .003" type="box" rgba="0.3 0.2 0.1 0.3" euler="0 0 -0.10"/>
                    <site name="sensorsurf3_0_2" pos="0.024 0.0060 0.000" size=".002 .002 .003" type="box" rgba="0.3 0.2 0.1 0.3" euler="0 0 -0.10"/>
                    <site name="sensorsurf3_0_3" pos="0.024 0.0060 -0.006" size=".002 .002 .003" type="box" rgba="0.3 0.2 0.1 0.3" euler="0 0 -0.10"/>  
                    <site name="sensorsurf3_1_1" pos="0.028 0.0053 0.006" size=".002 .002 .003" type="box" rgba="0.3 0.2 0.1 0.3" euler="0 0 -0.10"/>
                    <site name="sensorsurf3_1_2" pos="0.028 0.0053 0.000" size=".002 .002 .003" type="box" rgba="0.3 0.2 0.1 0.3" euler="0 0 -0.10"/>
                    <site name="sensorsurf3_1_3" pos="0.028 0.0053 -0.006" size=".002 .002 .003" type="box" rgba="0.3 0.2 0.1 0.3" euler="0 0 -0.10"/>  
                    <site name="sensorsurf3_2_1" pos="0.032 0.0047 0.006" size=".002 .002 .003" type="box" rgba="0.3 0.2 0.1 0.3" euler="0 0 -0.10"/>
                    <site name="sensorsurf3_2_2" pos="0.032 0.0047 0.000" size=".002 .002 .003" type="box" rgba="0.3 0.2 0.1 0.3" euler="0 0 -0.10"/>
                    <site name="sensorsurf3_2_3" pos="0.032 0.0047 -0.006" size=".002 .002 .003" type="box" rgba="0.3 0.2 0.1 0.3" euler="0 0 -0.10"/>  
                    <site name="sensorsurf3_3_1" pos="0.036 0.004 0.006" size=".002 .002 .003" type="box" rgba="0.3 0.2 0.1 0.3" euler="0 0 -0.20"/>
                    <site name="sensorsurf3_3_2" pos="0.036 0.004 0.000" size=".002 .002 .003" type="box" rgba="0.3 0.2 0.1 0.3" euler="0 0 -0.20"/>
                    <site name="sensorsurf3_3_3" pos="0.036 0.004 -0.006" size=".002 .002 .003" type="box" rgba="0.3 0.2 0.1 0.3" euler="0 0 -0.20"/>                                                            
                    <site name="sensorsurf3_4_1" pos="0.04 0.0035 0.006" size=".002 .002 .003" type="box" rgba="0.3 0.2 0.1 0.3" euler="0 0 -0.20"/>
                    <site name="sensorsurf3_4_2" pos="0.04 0.0035 0.000" size=".002 .002 .003" type="box" rgba="0.3 0.2 0.1 0.3" euler="0 0 -0.20"/>
                    <site name="sensorsurf3_4_3" pos="0.04 0.0035 -0.006" size=".002 .002 .003" type="box" rgba="0.3 0.2 0.1 0.3" euler="0 0 -0.20"/>
                    <site name="sensorsurf3_5_1" pos="0.044 0.0026 0.006" size=".002 .002 .003" type="box" rgba="0.3 0.2 0.1 0.3" euler="0 0 -0.20"/>
                    <site name="sensorsurf3_5_2" pos="0.044 0.0026 0.000" size=".002 .002 .003" type="box" rgba="0.3 0.2 0.1 0.3" euler="0 0 -0.20"/>
                    <site name="sensorsurf3_5_3" pos="0.044 0.0026 -0.006" size=".002 .002 .003" type="box" rgba="0.3 0.2 0.1 0.3" euler="0 0 -0.20"/>
                    <site name="sensorsurf3_6_1" pos="0.048 0.0018 0.006" size=".002 .002 .003" type="box" rgba="0.3 0.2 0.1 0.3" euler="0 0 -0.20"/>
                    <site name="sensorsurf3_6_2" pos="0.048 0.0018 0.000" size=".002 .002 .003" type="box" rgba="0.3 0.2 0.1 0.3" euler="0 0 -0.20"/>
                    <site name="sensorsurf3_6_3" pos="0.048 0.0018 -0.006" size=".002 .002 .003" type="box" rgba="0.3 0.2 0.1 0.3" euler="0 0 -0.20"/>
                    <site name="sensorsurf3_7_1" pos="0.052 0.0000 0.006" size=".002 .002 .003" type="box" rgba="0.3 0.2 0.1 0.3" euler="0 0 -0.20"/>
                    <site name="sensorsurf3_7_2" pos="0.052 0.0000 0.000" size=".002 .002 .003" type="box" rgba="0.3 0.2 0.1 0.3" euler="0 0 -0.20"/>
                    <site name="sensorsurf3_7_3" pos="0.052 0.0000 -0.006" size=".002 .002 .003" type="box" rgba="0.3 0.2 0.1 0.3" euler="0 0 -0.20"/>
            </body>
        </body>
    </body>
</mujocoinclude> 