<!-- ======================================================

    A ball on a string intended to be used for ball in cup.

    === HOW TO USE ===
    Mujoco's include statement does not support attaching to other bodies, so you need to copy
    everything inside the worldbody into your end-effector body. Note that the rope points in 
    +z direction. Do not forget to add the definitions in the default section to your model.
    In case your model gets unstable after pasting these parts try to lower your timestep.

    === HOW TO MODIFY ===
    Most properties can be changed in the 'default' section. It is not possible to create 
    defaults for bodies and inertials, so you will have to search and replace for:
        - link length: third value of pos in bodys
        - link mass and inertia: all values of the inertials

    Contact:     mail@kaiploeger.net
	Last edits:  14 Apr 20

====================================================== -->


<mujoco model="ball_on_string">

    <option integrator="Euler" timestep="0.002"/>
    <compiler coordinate="local" angle="radian" meshdir="meshes/"/>


    <default>
        <default class="joint_y">
            <joint pos="-0.00535 0 0" axis="0 1 0" group="3" limited="false" damping="0.0001" frictionloss="0"/>
        </default>

        <default class="joint_z">
            <joint pos="-0.00535 0 0" axis="0 0 1" group="3" limited="false" damping="0.0001" frictionloss="0"/>
        </default>
        
        <default class="chain_piece">         
            <geom size="0.001 0.00427" quat="0.707107 0 0.707107 0" type="capsule" contype="0" conaffinity="1" 
                group="3" rgba="0.5 0.6 0.7 1" density="0"/>
        </default>
        
        <default class="ball">
            <geom type="sphere" size="0.02" mass="0.021" contype="0" conaffinity="1" group="3" rgba="0.5 0.6 0.7 1"/>
        </default>

        <default class="chain_piece_visual">
            <geom size="0.001 0.00535" quat="0.707107 0 0.707107 0" type="capsule" contype="0" conaffinity="0" 
                group="2" rgba="0.7 0.7 0.7 1" density="0"/>
        </default>

        <default class="ball_visual">
            <geom type="sphere" size="0.02" contype="0" conaffinity="0" group="2" rgba="0.7 0.7 0.7 1" density="0"/>
        </default>
    </default>

 
    <worldbody>
        <body name="B0" euler="0 -1.57 0">
            <inertial pos="0 0 0" quat="0.707107 0 0.707107 0" mass="7.4927e-05" diaginertia="5.87e-10 5.87e-10 3.74635e-11"/>
            <joint name="J0_0" class="joint_y"/> 
            <joint name="J1_0" class="joint_z"/>
            <geom name="G0" class="chain_piece"/>
            <geom name="G0_vis" class="chain_piece_visual"/>

            <body name="B1" pos="0.0107 0 0">
                <inertial pos="0 0 0" quat="0.707107 0 0.707107 0" mass="7.4927e-05" diaginertia="5.87e-10 5.87e-10 3.74635e-11"/>
                <joint name="J0_1" class="joint_y"/>
                <joint name="J1_1" class="joint_z"/>
                <geom name="G1" class="chain_piece"/>
                <geom name="G1_vis" class="chain_piece_visual"/>
            
                <body name="B2" pos="0.0107 0 0">
                    <inertial pos="0 0 0" quat="0.707107 0 0.707107 0" mass="7.4927e-05" diaginertia="5.87e-10 5.87e-10 3.74635e-11"/>
                    <joint name="J0_2" class="joint_y"/>
                    <joint name="J1_2" class="joint_z"/>
                    <geom name="G2" class="chain_piece"/>
                    <geom name="G2_vis" class="chain_piece_visual"/>
                
                    <body name="B3" pos="0.0107 0 0">
                        <inertial pos="0 0 0" quat="0.707107 0 0.707107 0" mass="7.4927e-05" diaginertia="5.87e-10 5.87e-10 3.74635e-11"/>
                        <joint name="J0_3" class="joint_y"/>
                        <joint name="J1_3" class="joint_z"/>
                        <geom name="G3" class="chain_piece"/>
                        <geom name="G3_vis" class="chain_piece_visual"/>
                    
                        <body name="B4" pos="0.0107 0 0">
                            <inertial pos="0 0 0" quat="0.707107 0 0.707107 0" mass="7.4927e-05" diaginertia="5.87e-10 5.87e-10 3.74635e-11"/>
                            <joint name="J0_4" class="joint_y"/>
                            <joint name="J1_4" class="joint_z"/>
                            <geom name="G4" class="chain_piece"/>
                            <geom name="G4_vis" class="chain_piece_visual"/>
                        
                            <body name="B5" pos="0.0107 0 0">
                                <inertial pos="0 0 0" quat="0.707107 0 0.707107 0" mass="7.4927e-05" diaginertia="5.87e-10 5.87e-10 3.74635e-11"/>
                                <joint name="J0_5" class="joint_y"/>
                                <joint name="J1_5" class="joint_z"/>
                                <geom name="G5" class="chain_piece"/>
                                <geom name="G5_vis" class="chain_piece_visual"/>
                            
                                <body name="B6" pos="0.0107 0 0">
                                    <inertial pos="0 0 0" quat="0.707107 0 0.707107 0" mass="7.4927e-05" diaginertia="5.87e-10 5.87e-10 3.74635e-11"/>
                                    <joint name="J0_6" class="joint_y"/>
                                    <joint name="J1_6" class="joint_z"/>
                                    <geom name="G6" class="chain_piece"/>
                                    <geom name="G6_vis" class="chain_piece_visual"/>
                                
                                    <body name="B7" pos="0.0107 0 0">
                                        <inertial pos="0 0 0" quat="0.707107 0 0.707107 0" mass="7.4927e-05" diaginertia="5.87e-10 5.87e-10 3.74635e-11"/>
                                        <joint name="J0_7" class="joint_y"/>
                                        <joint name="J1_7" class="joint_z"/>
                                        <geom name="G7" class="chain_piece"/>
                                        <geom name="G7_vis" class="chain_piece_visual"/>
                                    
                                        <body name="B8" pos="0.0107 0 0">
                                            <inertial pos="0 0 0" quat="0.707107 0 0.707107 0" mass="7.4927e-05" diaginertia="5.87e-10 5.87e-10 3.74635e-11"/>
                                            <joint name="J0_8" class="joint_y"/>
                                            <joint name="J1_8" class="joint_z"/>
                                            <geom name="G8" class="chain_piece"/>
                                            <geom name="G8_vis" class="chain_piece_visual"/>
                                        
                                            <body name="B9" pos="0.0107 0 0">
                                                <inertial pos="0 0 0" quat="0.707107 0 0.707107 0" mass="7.4927e-05" diaginertia="5.87e-10 5.87e-10 3.74635e-11"/>
                                                <joint name="J0_9" class="joint_y"/>
                                                <joint name="J1_9" class="joint_z"/>
                                                <geom name="G9" class="chain_piece"/>
                                                <geom name="G9_vis" class="chain_piece_visual"/>
                                            
                                                <body name="B10" pos="0.0107 0 0">
                                                    <inertial pos="0 0 0" quat="0.707107 0 0.707107 0" mass="7.4927e-05" diaginertia="5.87e-10 5.87e-10 3.74635e-11"/>
                                                    <joint name="J0_10" class="joint_y"/>
                                                    <joint name="J1_10" class="joint_z"/>
                                                    <geom name="G10" class="chain_piece"/>
                                                    <geom name="G10_vis" class="chain_piece_visual"/>
                                                
                                                    <body name="B11" pos="0.0107 0 0">
                                                        <inertial pos="0 0 0" quat="0.707107 0 0.707107 0" mass="7.4927e-05" diaginertia="5.87e-10 5.87e-10 3.74635e-11"/>
                                                        <joint name="J0_11" class="joint_y"/>
                                                        <joint name="J1_11" class="joint_z"/>
                                                        <geom name="G11" class="chain_piece"/>
                                                        <geom name="G11_vis" class="chain_piece_visual"/>
                                                    
                                                        <body name="B12" pos="0.0107 0 0">
                                                            <inertial pos="0 0 0" quat="0.707107 0 0.707107 0" mass="7.4927e-05" diaginertia="5.87e-10 5.87e-10 3.74635e-11"/>
                                                            <joint name="J0_12" class="joint_y"/>
                                                            <joint name="J1_12" class="joint_z"/>
                                                            <geom name="G12" class="chain_piece"/>
                                                            <geom name="G12_vis" class="chain_piece_visual"/>
                                                        
                                                            <body name="B13" pos="0.0107 0 0">
                                                                <inertial pos="0 0 0" quat="0.707107 0 0.707107 0" mass="7.4927e-05" diaginertia="5.87e-10 5.87e-10 3.74635e-11"/>
                                                                <joint name="J0_13" class="joint_y"/>
                                                                <joint name="J1_13" class="joint_z"/>
                                                                <geom name="G13" class="chain_piece"/>
                                                                <geom name="G13_vis" class="chain_piece_visual"/>
                                                            
                                                                <body name="B14" pos="0.0107 0 0">
                                                                    <inertial pos="0 0 0" quat="0.707107 0 0.707107 0" mass="7.4927e-05" diaginertia="5.87e-10 5.87e-10 3.74635e-11"/>
                                                                    <joint name="J0_14" class="joint_y"/>
                                                                    <joint name="J1_14" class="joint_z"/>
                                                                    <geom name="G14" class="chain_piece"/>
                                                                    <geom name="G14_vis" class="chain_piece_visual"/>
                                                                
                                                                    <body name="B15" pos="0.0107 0 0">
                                                                        <inertial pos="0 0 0" quat="0.707107 0 0.707107 0" mass="7.4927e-05" diaginertia="5.87e-10 5.87e-10 3.74635e-11"/>
                                                                        <joint name="J0_15" class="joint_y"/>
                                                                        <joint name="J1_15" class="joint_z"/>
                                                                        <geom name="G15" class="chain_piece"/>
                                                                        <geom name="G15_vis" class="chain_piece_visual"/>
                                                                    
                                                                        <body name="B16" pos="0.0107 0 0">
                                                                            <inertial pos="0 0 0" quat="0.707107 0 0.707107 0" mass="7.4927e-05" diaginertia="5.87e-10 5.87e-10 3.74635e-11"/>
                                                                            <joint name="J0_16" class="joint_y"/>
                                                                            <joint name="J1_16" class="joint_z"/>
                                                                            <geom name="G16" class="chain_piece"/>
                                                                            <geom name="G16_vis" class="chain_piece_visual"/>
                                                                        
                                                                            <body name="B17" pos="0.0107 0 0">
                                                                                <inertial pos="0 0 0" quat="0.707107 0 0.707107 0" mass="7.4927e-05" diaginertia="5.87e-10 5.87e-10 3.74635e-11"/>
                                                                                <joint name="J0_17" class="joint_y"/>
                                                                                <joint name="J1_17" class="joint_z"/>
                                                                                <geom name="G17" class="chain_piece"/>
                                                                                <geom name="G17_vis" class="chain_piece_visual"/>
                                                                            
                                                                                <body name="B18" pos="0.0107 0 0">
                                                                                    <inertial pos="0 0 0" quat="0.707107 0 0.707107 0" mass="7.4927e-05" diaginertia="5.87e-10 5.87e-10 3.74635e-11"/>
                                                                                    <joint name="J0_18" class="joint_y"/>
                                                                                    <joint name="J1_18" class="joint_z"/>
                                                                                    <geom name="G18" class="chain_piece"/>
                                                                                    <geom name="G18_vis" class="chain_piece_visual"/>
                                                                                
                                                                                    <body name="B19" pos="0.0107 0 0">
                                                                                        <inertial pos="0 0 0" quat="0.707107 0 0.707107 0" mass="7.4927e-05" diaginertia="5.87e-10 5.87e-10 3.74635e-11"/>
                                                                                        <joint name="J0_19" class="joint_y"/>
                                                                                        <joint name="J1_19" class="joint_z"/>
                                                                                        <geom name="G19" class="chain_piece"/>
                                                                                        <geom name="G19_vis" class="chain_piece_visual"/>
                                                                                    
                                                                                        <body name="B20" pos="0.0107 0 0">
                                                                                            <inertial pos="0 0 0" quat="0.707107 0 0.707107 0" mass="7.4927e-05" diaginertia="5.87e-10 5.87e-10 3.74635e-11"/>
                                                                                            <joint name="J0_20" class="joint_y"/>
                                                                                            <joint name="J1_20" class="joint_z"/>
                                                                                            <geom name="G20" class="chain_piece"/>
                                                                                            <geom name="G20_vis" class="chain_piece_visual"/>
                                                                                        
                                                                                            <body name="B21" pos="0.0107 0 0">
                                                                                                <inertial pos="0 0 0" quat="0.707107 0 0.707107 0" mass="7.4927e-05" diaginertia="5.87e-10 5.87e-10 3.74635e-11"/>
                                                                                                <joint name="J0_21" class="joint_y"/>
                                                                                                <joint name="J1_21" class="joint_z"/>
                                                                                                <geom name="G21" class="chain_piece"/>
                                                                                                <geom name="G21_vis" class="chain_piece_visual"/>
                                                                                            
                                                                                                <body name="B22" pos="0.0107 0 0">
                                                                                                    <inertial pos="0 0 0" quat="0.707107 0 0.707107 0" mass="7.4927e-05" diaginertia="5.87e-10 5.87e-10 3.74635e-11"/>
                                                                                                    <joint name="J0_22" class="joint_y"/>
                                                                                                    <joint name="J1_22" class="joint_z"/>
                                                                                                    <geom name="G22" class="chain_piece"/>
                                                                                                    <geom name="G22_vis" class="chain_piece_visual"/>
                                                                                                
                                                                                                    <body name="B23" pos="0.0107 0 0">
                                                                                                        <inertial pos="0 0 0" quat="0.707107 0 0.707107 0" mass="7.4927e-05" diaginertia="5.87e-10 5.87e-10 3.74635e-11"/>
                                                                                                        <joint name="J0_23" class="joint_y"/>
                                                                                                        <joint name="J1_23" class="joint_z"/>
                                                                                                        <geom name="G23" class="chain_piece"/>
                                                                                                        <geom name="G23_vis" class="chain_piece_visual"/>
                                                                                                    
                                                                                                        <body name="B24" pos="0.0107 0 0">
                                                                                                            <inertial pos="0 0 0" quat="0.707107 0 0.707107 0" mass="7.4927e-05" diaginertia="5.87e-10 5.87e-10 3.74635e-11"/>
                                                                                                            <joint name="J0_24" class="joint_y"/>
                                                                                                            <joint name="J1_24" class="joint_z"/>
                                                                                                            <geom name="G24" class="chain_piece"/>
                                                                                                            <geom name="G24_vis" class="chain_piece_visual"/>
                                                                                                        
                                                                                                            <body name="B25" pos="0.0107 0 0">
                                                                                                                <inertial pos="0 0 0" quat="0.707107 0 0.707107 0" mass="7.4927e-05" diaginertia="5.87e-10 5.87e-10 3.74635e-11"/>
                                                                                                                <joint name="J0_25" class="joint_y"/>
                                                                                                                <joint name="J1_25" class="joint_z"/>
                                                                                                                <geom name="G25" class="chain_piece"/>
                                                                                                                <geom name="G25_vis" class="chain_piece_visual"/>
                                                                                                            
                                                                                                                <body name="B26" pos="0.0107 0 0">
                                                                                                                    <inertial pos="0 0 0" quat="0.707107 0 0.707107 0" mass="7.4927e-05" diaginertia="5.87e-10 5.87e-10 3.74635e-11"/>
                                                                                                                    <joint name="J0_26" class="joint_y"/> 
                                                                                                                    <joint name="J1_26" class="joint_z"/>
                                                                                                                    <geom name="G26" class="chain_piece"/>
                                                                                                                    <geom name="G26_vis" class="chain_piece_visual"/>
                                                                                                                
                                                                                                                    <body name="B27" pos="0.0107 0 0">
                                                                                                                        <inertial pos="0 0 0" quat="0.707107 0 0.707107 0" mass="7.4927e-05" diaginertia="5.87e-10 5.87e-10 3.74635e-11"/>
                                                                                                                        <joint name="J0_27" class="joint_y"/>
                                                                                                                        <joint name="J1_27" class="joint_z"/>
                                                                                                                        <geom name="G27" class="chain_piece"/>
                                                                                                                        <geom name="G27_vis" class="chain_piece_visual"/>
                                                                                                                    
                                                                                                                        <body name="B28" pos="0.0107 0 0">
                                                                                                                            <inertial pos="0 0 0" quat="0.707107 0 0.707107 0" mass="7.4927e-05" diaginertia="5.87e-10 5.87e-10 3.74635e-11"/>
                                                                                                                            <joint name="J0_28" class="joint_y"/>
                                                                                                                            <joint name="J1_28" class="joint_z"/>
                                                                                                                            <geom name="G28" class="chain_piece"/>
                                                                                                                            <geom name="G28_vis" class="chain_piece_visual"/>
                                                                                                                        
                                                                                                                            <body name="B29" pos="0.0107 0 0">
                                                                                                                                <inertial pos="0 0 0" quat="0.707107 0 0.707107 0" mass="7.4927e-05" diaginertia="5.87e-10 5.87e-10 3.74635e-11"/>
                                                                                                                                <joint name="J0_29" class="joint_y"/>
                                                                                                                                <joint name="J1_29" class="joint_z"/>
                                                                                                                                <geom name="G29" class="chain_piece"/>
                                                                                                                                <geom name="G29_vis" class="chain_piece_visual"/>
                                                                                                                            
                                                                                                                                <body name="ball" pos="0.0255 0 0">
                                                                                                                                    <geom class="ball" name="ball_geom"/>
                                                                                                                                    <geom class="ball_visual" name="ball_geom_visual"/>
                                                                                                                                </body>
                                                                                                                            </body>
                                                                                                                        </body>
                                                                                                                    </body>
                                                                                                                </body>
                                                                                                            </body>
                                                                                                        </body>
                                                                                                    </body>
                                                                                                </body>
                                                                                            </body>
                                                                                        </body>
                                                                                    </body>
                                                                                </body>
                                                                            </body>
                                                                        </body>
                                                                    </body>
                                                                </body>
                                                            </body>
                                                        </body>
                                                    </body>
                                                </body>
                                            </body>
                                        </body>
                                    </body>
                                </body>
                            </body>
                        </body>
                    </body>
                </body>
            </body>
        </body>
    </worldbody>
</mujoco>
